<?xml version="1.0"?>

<robot name="test_robot">

	<link name="base_link">
		<visual>
			<geometry>
				<box size="0.35 0.35 0.07"/>
			</geometry>
			<origin rpy="0 0 0" xyz="0 0 0.07"/>
			<material name="white">
				<color rgba="1 1 1 1"/>
			</material>
		</visual>
		<collision>
			<geometry>
				<box size="0.35 0.35 0.07"/>
			</geometry>
			<origin rpy="0 0 0" xyz="0 0 0.07"/>
		</collision>
		<inertial>
			<mass value="10"/>
			<inertia ixx="0.1062" ixy="0.0" ixz="0.0" iyy="0.1062" iyz="0.0" izz="0.2042"/>
			<origin rpy="0 0 0" xyz="0 0 0.07"/>
		</inertial>

	</link>

	<link name="lwheel">
		<visual>
			<geometry>
				<cylinder length="0.01" radius="0.07"/>
			</geometry>
			<origin rpy="0 0 0" xyz="0 0 0"/>
			<material name="black">
				<color rgba="0 0 0 1"/>
			</material>
		</visual>
		<collision>
			<geometry>
				<cylinder length="0.01" radius="0.07"/>
			</geometry>
			<origin rpy="0 0 0" xyz="0 0 0"/>
		</collision>
		<inertial>
			<mass value="1"/>
			<inertia ixx="0.0012" ixy="0.0" ixz="0.0" iyy="0.0012" iyz="0.0" izz="0.0025"/>
			<origin rpy="0 0 0" xyz="0 0 0"/>
		</inertial>
	</link>

	<joint name="base_to_lwheel" type="continuous">
		<parent link="base_link"/>
		<child link="lwheel"/>
		<origin xyz="0 0.18 0.07" rpy="1.5708 0 0"/>
		<axis xyz="0.0 0.0 -1.0"/>
	</joint>

	<link name="slwheel">
		<visual>
			<geometry>
				<box size="0.05 0.005 0.05"/>
			</geometry>
			<origin rpy="0 0 0" xyz="0 0 0"/>
			<material name="white">
				<color rgba="1 1 1 1"/>
			</material>
		</visual>
		<collision>
			<geometry>
				<box size="0.05 0.005 0.05"/>
			</geometry>
			<origin rpy="0 0 0" xyz="0 0 0"/>
		</collision>
		<inertial>
			<mass value="0.1"/>
			<inertia ixx="0.00002104" ixy="0.0" ixz="0.0" iyy="0.00004167" iyz="0.0" izz="0.00002104"/>
			<origin rpy="0 0 0" xyz="0 0 0"/>
		</inertial>
	</link>

	<joint name="base_to_slwheel" type="continuous">
		<parent link="lwheel"/>
		<child link="slwheel"/>
		<origin xyz="0 0 0.365" rpy="1.5708 0 0"/>
		<axis xyz="0.0 1.0 0.0"/>
	</joint>

	<link name="rwheel">
		<visual>
			<geometry>
				<cylinder length="0.01" radius="0.07"/>
			</geometry>
			<origin rpy="0 0 0" xyz="0 0 0"/>
			<material name="black">
				<color rgba="0 0 0 1"/>
			</material>
		</visual>
		<collision>
			<geometry>
				<cylinder length="0.01" radius="0.07"/>
			</geometry>
			<origin rpy="0 0 0" xyz="0 0 0"/>
		</collision>
		<inertial>
			<mass value="1"/>
			<inertia ixx="0.0012" ixy="0.0" ixz="0.0" iyy="0.0012" iyz="0.0" izz="0.0025"/>
			<origin rpy="0 0 0" xyz="0 0 0"/>
		</inertial>
	</link>

	<joint name="base_to_rwheel" type="continuous">
		<parent link="base_link"/>
		<child link="rwheel"/>
		<origin xyz="0 -0.18 0.07" rpy="1.5708 0 0"/>
		<axis xyz="0.0 0.0 -1.0"/>
	</joint>	

	<link name="srwheel">
		<visual>
			<geometry>
				<box size="0.05 0.005 0.05"/>
			</geometry>
			<origin rpy="0 0 0" xyz="0 0 0"/>
			<material name="white">
				<color rgba="1 1 1 1"/>
			</material>
		</visual>
		<collision>
			<geometry>
				<box size="0.05 0.005 0.05"/>
			</geometry>
			<origin rpy="0 0 0" xyz="0 0 0"/>
		</collision>
		<inertial>
			<mass value="1"/>
			<inertia ixx="0.00002104" ixy="0.0" ixz="0.0" iyy="0.00004167" iyz="0.0" izz="0.00002104"/>
			<origin rpy="0 0 0" xyz="0 0 0"/>
		</inertial>
	</link>

	<joint name="base_to_srwheel" type="continuous">
		<parent link="rwheel"/>
		<child link="srwheel"/>
		<origin xyz="0 0 -0.365" rpy="1.5708 0 0"/>
		<axis xyz="0.0 1.0 0.0"/>
	</joint>

	<link name="fwheel_attach">
		<visual>
			<geometry>
				<sphere radius="0.0175"/>
			</geometry>
			<origin rpy="0 0 0" xyz="0 0 0"/>
			<material name="black">
				<color rgba="0 0 0 1"/>
			</material>
		</visual>	
		<collision>
			<geometry>
				<sphere radius="0.0175"/>
			</geometry>
			<origin rpy="0 0 0" xyz="0 0 0"/>
		</collision>	
		<inertial>
			<mass value="0.5"/>
			<inertia ixx="0.00006125" ixy="0.0" ixz="0.0" iyy="0.00006125" iyz="0.0" izz="0.00006125"/>
			<origin rpy="0 0 0" xyz="0 0 0"/>
		</inertial>
	</link>

	<joint name="base_to_fattach" type="continuous">
		<parent link="base_link"/>
		<child link="fwheel_attach"/>
		<origin xyz="0.13 0 0.0175" rpy="0 0 0"/>
		<axis xyz="1.0 1.0 1.0"/>
	</joint>

	<link name="bwheel_attach">
		<visual>
			<geometry>
				<sphere radius="0.0175"/>
			</geometry>
			<origin rpy="0 0 0" xyz="0 0 0"/>
			<material name="black">
				<color rgba="0 0 0 1"/>
			</material>
		</visual>	
		<collision>
			<geometry>
				<sphere radius="0.0175"/>
			</geometry>
			<origin rpy="0 0 0" xyz="0 0 0"/>
		</collision>
		<inertial>
			<mass value="0.5"/>
			<inertia ixx="0.00002" ixy="0.0" ixz="0.0" iyy="0.00002" iyz="0.0" izz="0.0002"/>
			<origin rpy="0 0 0" xyz="0 0 0"/>
		</inertial>		
	</link>

	<joint name="base_to_battach" type="continuous">
		<parent link="base_link"/>
		<child link="bwheel_attach"/>
		<origin xyz="-0.13 0 0.0175" rpy="0 0 0"/>
		<axis xyz="1.0 1.0 1.0"/>
	</joint>

	<!-- Hokuyo Laser -->

	<link name="hokuyo_link">
		<collision>
			<origin xyz="0 0 0" rpy="0 0 0"/>
			<geometry>
				<box size="0.1 0.1 0.1"/>
			</geometry>
		</collision>

		<visual>
			<origin xyz="0 0 0" rpy="0 0 0"/>
			<geometry>
				<mesh filename="package://fra503_project_diff/Models/hokuyo.dae"/>
			</geometry>
		</visual>

		<inertial>
			<mass value="1e-5" />
			<origin xyz="0 0 0" rpy="0 0 0"/>
			<inertia ixx="1e-6" ixy="0" ixz="0" iyy="1e-6" iyz="0" izz="1e-6" />
		</inertial>
	</link>

	<joint name="hokuyo_joint" type="fixed">
		<axis xyz="0 1 0" />
		<!-- <origin xyz="0.1 0 0.14" rpy="0 0 0"/> -->
		<origin xyz="0.1 0 0.3" rpy="0 0 0"/>
		<parent link="base_link"/>
		<child link="hokuyo_link"/>
	</joint>

	<transmission name="left_wheel_transmission">
		<type>transmission_interface/SimpleTransmission</type>
		<joint name="base_to_lwheel">
		<hardwareInterface>hardware_interface/VelocityJointInterface</hardwareInterface>  
		</joint>
		<actuator name="left_wheel_actuator">
		<mechanicalReduction>7</mechanicalReduction>
		<hardwareInterface>VelocityJointInterface</hardwareInterface>
		</actuator>
	</transmission>

	<transmission name="right_wheel_transmission">
		<type>transmission_interface/SimpleTransmission</type>
		<joint name="base_to_rwheel">
		<hardwareInterface>hardware_interface/VelocityJointInterface</hardwareInterface>  
		</joint>
		<actuator name="right_wheel_actuator">
		<mechanicalReduction>7</mechanicalReduction>
		<hardwareInterface>VelocityJointInterface</hardwareInterface>
		</actuator>
	</transmission>

  	<!-- ROS Control plugin for Gazebo -->
	<gazebo>
		<plugin name="gazebo_ros_control" filename="libgazebo_ros_control.so">
		</plugin>
	</gazebo>

	<gazebo reference="rwheel">
    	<mu1>10</mu1>
    	<mu2>10</mu2>
    	<material>Gazebo/Black</material>
  	</gazebo>

	<gazebo reference="lwheel">
    	<mu1>10</mu1>
    	<mu2>10</mu2>
    	<material>Gazebo/Black</material>
  	</gazebo>

	<gazebo reference="fwheel_attach">
    	<mu1>0.0001</mu1>
    	<mu2>0.0001</mu2>
    	<material>Gazebo/Black</material>
  	</gazebo>

	<gazebo reference="bwheel_attach">
    	<mu1>0.0001</mu1>
    	<mu2>0.0001</mu2>
    	<material>Gazebo/Black</material>
  	</gazebo>

	<!-- hokuyo -->
	<gazebo reference="hokuyo_link">
		<sensor type="gpu_ray" name="head_hokuyo_sensor">
			<pose>0 0 0 0 0 0</pose>
			<visualize>true</visualize>
			<update_rate>40</update_rate>
			<ray>
				<scan>
					<horizontal>
						<samples>720</samples>
						<resolution>1</resolution>
						<min_angle>-1.570796</min_angle>
						<max_angle>1.570796</max_angle>
					</horizontal>
				</scan>
				<range>
					<min>0.10</min>
					<max>30.0</max>
					<resolution>0.01</resolution>
				</range>
				<noise>
					<type>gaussian</type>
					<!-- Noise parameters based on published spec for Hokuyo laser
						achieving "+-30mm" accuracy at range < 10m.  A mean of 0.0m and
						stddev of 0.01m will put 99.7% of samples within 0.03m of the true
						reading. -->
					<mean>0.0</mean>
					<stddev>0.01</stddev>
				</noise>
			</ray>
			<plugin name="gazebo_ros_head_hokuyo_controller" filename="libgazebo_ros_gpu_laser.so">
				<topicName>scan</topicName>
				<frameName>hokuyo_link</frameName>
			</plugin>
		</sensor>
	</gazebo>

</robot>
